<?xml version="1.0"?>
<robot xmlns:xacro="http://wiki.ros.org/xacro">
  <xacro:include filename="$(find fanuc_resources)/urdf/common_materials.xacro"/>

  <xacro:macro name="fanuc_r1000ia100f" params="prefix">
    <!-- links: main serial chain -->
    <link name="${prefix}base_link">
      <visual>
        <origin xyz="0 0 0" rpy="0 0 0"/>
        <geometry>
          <mesh filename="package://fanuc_r1000ia_support/meshes/r1000ia100f/base_link.dae"/>
        </geometry>
        <xacro:material_fanuc_gray40 />
      </visual>
      <collision>
        <origin xyz="0 0 0" rpy="0 0 0"/>
        <geometry>
          <mesh filename="package://fanuc_r1000ia_support/meshes/r1000ia100f/base_link.dae"/>
        </geometry>
      </collision>
    </link>
    <link name="${prefix}link_1">
      <visual>
        <origin xyz="0 0 0" rpy="0 0 0"/>
        <geometry>
          <mesh filename="package://fanuc_r1000ia_support/meshes/r1000ia100f/link_1.dae"/>
        </geometry>
      </visual>
      <collision>
        <origin xyz="0 0 0" rpy="0 0 0"/>
        <geometry>
          <mesh filename="package://fanuc_r1000ia_support/meshes/r1000ia100f/link_1.dae"/>
        </geometry>
      </collision>
    </link>
    <link name="${prefix}link_2">
      <visual>
        <origin xyz="0 0 0" rpy="0 0 0"/>
        <geometry>
          <mesh filename="package://fanuc_r1000ia_support/meshes/r1000ia100f/link_2.dae"/>
        </geometry>
      </visual>
      <collision>
        <origin xyz="0 0 0" rpy="0 0 0"/>
        <geometry>
          <mesh filename="package://fanuc_r1000ia_support/meshes/r1000ia100f/link_2.dae"/>
        </geometry>
      </collision>
    </link>
    <link name="${prefix}link_3">
      <visual>
        <origin xyz="0 0 0" rpy="0 0 0"/>
        <geometry>
          <mesh filename="package://fanuc_r1000ia_support/meshes/r1000ia100f/link_3.dae"/>
        </geometry>
      </visual>
      <collision>
        <origin xyz="0 0 0" rpy="0 0 0"/>
        <geometry>
          <mesh filename="package://fanuc_r1000ia_support/meshes/r1000ia100f/link_3.dae"/>
        </geometry>
      </collision>
    </link>
    <link name="${prefix}link_4">
      <visual>
        <origin xyz="0 0 0" rpy="0 0 0"/>
        <geometry>
          <mesh filename="package://fanuc_r1000ia_support/meshes/r1000ia100f/link_4.dae"/>
        </geometry>
      </visual>
      <collision>
        <origin xyz="0 0 0" rpy="0 0 0"/>
        <geometry>
          <mesh filename="package://fanuc_r1000ia_support/meshes/r1000ia100f/link_4.dae"/>
        </geometry>
      </collision>
    </link>
    <link name="${prefix}link_5">
      <visual>
        <origin xyz="0 0 0" rpy="0 0 0"/>
        <geometry>
          <mesh filename="package://fanuc_r1000ia_support/meshes/r1000ia100f/link_5.dae"/>
        </geometry>
      </visual>
      <collision>
        <origin xyz="0 0 0" rpy="0 0 0"/>
        <geometry>
          <mesh filename="package://fanuc_r1000ia_support/meshes/r1000ia100f/link_5.dae"/>
        </geometry>
      </collision>
    </link>
    <link name="${prefix}link_6">
      <visual>
        <origin xyz="0 0 0" rpy="0 0 0"/>
        <geometry>
          <mesh filename="package://fanuc_r1000ia_support/meshes/r1000ia100f/link_6.dae"/>
        </geometry>
        <xacro:material_fanuc_black />
      </visual>
      <collision>
        <origin xyz="0 0 0" rpy="0 0 0"/>
        <geometry>
          <mesh filename="package://fanuc_r1000ia_support/meshes/r1000ia100f/link_6.dae"/>
        </geometry>
      </collision>
    </link>

    <!-- joints: main serial chain -->
    <joint name="${prefix}joint_1" type="revolute">
      <origin xyz="0 0 0.304" rpy="0 0 0"/>
      <parent link="${prefix}base_link"/>
      <child link="${prefix}link_1"/>
      <axis xyz="0 0 1"/>
      <limit lower="-3.1415" upper="3.1415" effort="0" velocity="2.9671"/>
    </joint>
    <joint name="${prefix}joint_2" type="revolute">
      <origin xyz="0.320 0.094 0.187" rpy="0 0 0"/>
      <parent link="${prefix}link_1"/>
      <child link="${prefix}link_2"/>
      <axis xyz="0 1 0"/>
      <limit lower="-1.5707" upper="2.7052" effort="0" velocity="2.4434"/>
    </joint>
    <joint name="${prefix}joint_3" type="revolute">
      <origin xyz="0 0.064 0.870" rpy="0 0 0"/>
      <parent link="${prefix}link_2"/>
      <child link="${prefix}link_3"/>
      <axis xyz="0 -1 0"/>
      <limit lower="-3.1415" upper="3.1415" effort="0" velocity="2.7925"/>
    </joint>
    <joint name="${prefix}joint_4" type="revolute">
      <origin xyz="0.822 -0.154 0.225" rpy="0 0 0"/>
      <parent link="${prefix}link_3"/>
      <child link="${prefix}link_4"/>
      <axis xyz="-1 0 0"/>
      <limit lower="-6.2831" upper="6.2831" effort="0" velocity="4.0142"/>
    </joint>
    <joint name="${prefix}joint_5" type="revolute">
      <origin xyz="0.18 -0.033 0" rpy="0 0 0"/>
      <parent link="${prefix}link_4"/>
      <child link="${prefix}link_5"/>
      <axis xyz="0 -1 0"/>
      <limit lower="-2.1816" upper="2.1816" effort="0" velocity="4.0142"/>
    </joint>
    <joint name="${prefix}joint_6" type="revolute">
      <origin xyz="0.168 0.033 0" rpy="0 0 0"/>
      <parent link="${prefix}link_5"/>
      <child link="${prefix}link_6"/>
      <axis xyz="-1 0 0"/>
      <limit lower="-6.2831" upper="6.2831" effort="0" velocity="6.1086"/>
    </joint>

    <!-- ROS-Industrial 'base' frame: base_link to Fanuc World Coordinates transform -->
    <link name="${prefix}base" />
    <joint name="${prefix}base_link-base" type="fixed">
      <origin xyz="0 0 0.450" rpy="0 0 0"/>
      <parent link="${prefix}base_link"/>
      <child link="${prefix}base"/>
    </joint>

    <!-- ROS-Industrial 'flange' frame: attachment point for EEF models -->
    <link name="${prefix}flange" />
    <joint name="${prefix}joint_6-flange" type="fixed">
      <origin xyz="0 0 0" rpy="0 0 0" />
      <parent link="${prefix}link_6" />
      <child link="${prefix}flange" />
    </joint>

    <!-- ROS-Industrial 'tool0' frame: all-zeros tool frame -->
    <link name="${prefix}tool0" />
    <joint name="${prefix}link_6-tool0" type="fixed">
      <origin xyz="0 0 0" rpy="${pi} ${-pi/2.0} 0" />
      <parent link="${prefix}flange" />
      <child link="${prefix}tool0" />
    </joint>
  </xacro:macro>
</robot>
